try:
    raise Exception()
finally:
    pass